<?xml version='1.0'?>
<!--
<robot name="robot_state_publisher">
-->
<robot name="myrobot" xmlns:xacro="http://www.ros.org/wiki/xacro">
<!--Chassis  Link /-->

 <link name='chassis'>

   <visual name='chassis_visual'>

      <origin xyz="0 0 .3" rpy=" 0 0 0"/>

      <geometry>
        <box size="1. .6 .6"/>
      </geometry>

    </visual>    
     
   <inertial>

      <mass value="20.0"/>
      <origin xyz="0 0 0.3" rpy=" 0 0 0"/>
      <inertia
          ixx="0.5" ixy="0" ixz="0"
          iyy="1.0" iyz="0"
          izz="0.1"
      />

   </inertial>

   <collision name='collision'>
      <geometry>
        <box size="1. .6 .6"/>
      </geometry>
   </collision>
</link>

<!-- ++++++++++++++++three Left wheels joints+++++++++++++++++++++++++++++++ /-->



  <joint name="joint1" type="continuous">
    <parent link="chassis"/>
    <child link="link1"/>
    <origin xyz="0.5 0.3 0" rpy="0 0 0"/>
    <axis xyz="0 1 0" rpy="0 0 0"/>
    <limit effort="100" velocity="100"/>
    <joint_properties damping="0.0" friction="0.0"/>
  </joint>

 <joint name="joint2" type="continuous">
    <parent link="chassis"/>
    <child link="link2"/>
   <origin xyz="0 0.3 0" rpy="0 0 0"/>
    <axis xyz="0 1 0" rpy="0 0 0"/>
    <limit effort="100" velocity="100"/>
    <joint_properties damping="0.0" friction="0.0"/>
  </joint>

  <joint name="joint3" type="continuous">
    <parent link="chassis"/>
    <child link="link3"/>
    <origin xyz="-0.5 0.3 0" rpy="0 0 0"/>
    <axis xyz="0 1 0" rpy="0 0 0"/>
    <limit effort="100" velocity="100"/>
    <joint_properties damping="0.0" friction="0.0"/>
  </joint>

<!-- ++++++++++++++++three right wheels joints+++++++++++++++++++++++++++++++ /-->



 <joint name="joint4" type="continuous">
    <parent link="chassis"/>
    <child link="link4"/>
    <origin xyz="0.5 -0.3 0" rpy="0 0 0"/>
    <axis xyz="0 1 0" rpy="0 0 0"/>
    <limit effort="100" velocity="100"/>
    <joint_properties damping="0.0" friction="0.0"/>
  </joint>

<joint name="joint5" type="continuous">
    <parent link="chassis"/>
    <child link="link5"/>
   <origin xyz="0 -0.3 0" rpy="0 0 0"/>
    <axis xyz="0 1 0" rpy="0 0 0"/>
    <limit effort="100" velocity="100"/>
    <joint_properties damping="0.0" friction="0.0"/>
  </joint>

  <joint name="joint6" type="continuous">
    <parent link="chassis"/>
    <child link="link6"/>
    <origin xyz="-0.5 -0.3 0" rpy="0 0 0"/>
    <axis xyz="0 1 0" rpy="0 0 0"/>
    <limit effort="100" velocity="100"/>
    <joint_properties damping="0.0" friction="0.0"/>
  </joint>



<!--three left wheel Links /-->

 

<link name="link1">

    <visual name="left_wheel_visual">
      <origin xyz="0 0 0" rpy="0 1.5707 1.5707"/>
      <geometry>
        <cylinder radius="0.2" length="0.1"/>
      </geometry>
    </visual>


    <collision name="collision">
      <origin xyz="0 0 0" rpy="0 1.5707 1.5707"/>
      <geometry>
        <cylinder radius="0.2" length="0.1"/>
      </geometry>
    </collision>

    

    <inertial>
      <origin xyz="0 0 0" rpy="0 1.5707 1.5707"/>
      <mass value="5"/>
      <cylinder_inertia m="5" r="0.1" h="0.05"/>
      <inertia
        ixx="1.0" ixy="0.0" ixz="0.0"
        iyy="1.0" iyz="0.0"
        izz="1.0"/>
    </inertial>

 </link>


<link name="link2">

    <visual name="left2_wheel_visual">
      <origin xyz="0 0 0" rpy="0 1.5707 1.5707"/>
      <geometry>
        <cylinder radius="0.2" length="0.1"/>
      </geometry>
    </visual>


    <collision name="collision">
      <origin xyz="0 0 0" rpy="0 1.5707 1.5707"/>
      <geometry>
        <cylinder radius="0.2" length="0.1"/>
      </geometry>
    </collision>

    

    <inertial>
      <origin xyz="0 0 0" rpy="0 1.5707 1.5707"/>
      <mass value="5"/>
      <cylinder_inertia m="5" r="0.1" h="0.05"/>
      <inertia
        ixx="1.0" ixy="0.0" ixz="0.0"
        iyy="1.0" iyz="0.0"
        izz="1.0"/>
    </inertial>

 </link>

<link name="link3">

    <visual name="left3_wheel_visual">
      <origin xyz="0 0 0" rpy="0 1.5707 1.5707"/>
      <geometry>
        <cylinder radius="0.2" length="0.1"/>
      </geometry>
    </visual>


    <collision name="collision">
      <origin xyz="0 0 0" rpy="0 1.5707 1.5707"/>
      <geometry>
        <cylinder radius="0.2" length="0.1"/>
      </geometry>
    </collision>

    

    <inertial>
      <origin xyz="0 0 0" rpy="0 1.5707 1.5707"/>
      <mass value="5"/>
      <cylinder_inertia m="5" r="0.1" h="0.05"/>
      <inertia
        ixx="1.0" ixy="0.0" ixz="0.0"
        iyy="1.0" iyz="0.0"
        izz="1.0"/>
    </inertial>

 </link>




<!--three Right Wheel links /-->

  <link name="link4">

    <visual name="right_wheel_visual">

      <origin xyz="0 0 0" rpy="0 1.5707 1.5707"/>

      <geometry>
        <cylinder radius="0.2" length="0.1"/>
      </geometry>

    </visual>

    
    <collision name="collision">

      <origin xyz="0 0 0" rpy="0 1.5707 1.5707"/>

      <geometry>
        <cylinder radius="0.2" length="0.1"/>
      </geometry>

    </collision>


    <inertial>

      <origin xyz="0 0 0" rpy="0 1.5707 1.5707"/>
      <mass value="5"/>
      <cylinder_inertia m="5" r="0.1" h="0.05"/>

      <inertia
        ixx="1.0" ixy="0.0" ixz="0.0"
        iyy="1.0" iyz="0.0"
        izz="1.0"/>
      </inertial>

  </link>



<link name="link5">

    <visual name="right4_wheel_visual">

      <origin xyz="0 0 0" rpy="0 1.5707 1.5707"/>

      <geometry>
        <cylinder radius="0.2" length="0.1"/>
      </geometry>

    </visual>

    
    <collision name="collision">

      <origin xyz="0 0 0" rpy="0 1.5707 1.5707"/>

      <geometry>
        <cylinder radius="0.2" length="0.1"/>
      </geometry>

    </collision>


    <inertial>

      <origin xyz="0 0 0" rpy="0 1.5707 1.5707"/>
      <mass value="5"/>
      <cylinder_inertia m="5" r="0.1" h="0.05"/>

      <inertia
        ixx="1.0" ixy="0.0" ixz="0.0"
        iyy="1.0" iyz="0.0"
        izz="1.0"/>
      </inertial>

  </link>


<link name="link6">

    <visual name="right11_wheel_visual">

      <origin xyz="0 0 0" rpy="0 1.5707 1.5707"/>

      <geometry>
        <cylinder radius="0.2" length="0.1"/>
      </geometry>

    </visual>

    
    <collision name="collision">

      <origin xyz="0 0 0" rpy="0 1.5707 1.5707"/>

      <geometry>
        <cylinder radius="0.2" length="0.1"/>
      </geometry>

    </collision>


    <inertial>

      <origin xyz="0 0 0" rpy="0 1.5707 1.5707"/>
      <mass value="5"/>
      <cylinder_inertia m="5" r="0.1" h="0.05"/>

      <inertia
        ixx="1.0" ixy="0.0" ixz="0.0"
        iyy="1.0" iyz="0.0"
        izz="1.0"/>
      </inertial>

  </link>



<!-- ++++++++++++++++++  Kinect  +++++++++++++++++++++++++++++ /-->
<!--kinect joint /-->

<joint name="kinect_joint" type="fixed">

    <origin xyz=".15 0 .05" rpy="0 0 0"/>

    <parent link="chassis"/>
    <child link="camera_link"/>

</joint>


<!--Kinect  Link /-->

<link name="camera_link">
    
 <visual>

      <origin xyz="0 0 0.05" rpy="0 0 0"/>

      <geometry>

      <mesh filename="package://mybot_description/meshes/kinect.dae"/>

      </geometry>

 </visual>
    

 <collision>
    <origin xyz="0 0 0" rpy="0 0 0"/>

    <geometry>
    <box size="0.1 0.1 0.1"/>
    </geometry>
    
 </collision>

 <inertial>
     <mass value="1e-5" />
     <origin xyz="0 0 0" rpy="0 0 0"/>
     <inertia ixx="1e-6" ixy="0" ixz="0" iyy="1e-6" iyz="0" izz="1e-6" />
 </inertial>


</link>



<!--  Kinect Optical Link and joints   /-->

<joint name="kinect_optical_joint" type="fixed">

<origin xyz="0 0 0" rpy="-1.5707 0 -1.5707"/> <!-- To invert the coordinates from image convention (Z is forward) to normal xyz /-->
<parent link="camera_link"/>
<child link="kinect_optical"/>
</joint>

<!--Virtual link to project the images to, and then flip it to us as its joint is flipped  /-->
<link name="kinect_optical">
</link>










</robot>
